Traceback (most recent call last):
  File "C:\Users\mlee\anaconda3\Lib\site-packages\jupyter_cache\executors\utils.py", line 58, in single_nb_execution
    executenb(
  File "C:\Users\mlee\anaconda3\Lib\site-packages\nbclient\client.py", line 1305, in execute
    return NotebookClient(nb=nb, resources=resources, km=km, **kwargs).execute()
           ^^^^^^^^^^^^^^^^^^^^^^^^^^^^^^^^^^^^^^^^^^^^^^^^^^^^^^^^^^^^^^^^^^^^^
  File "C:\Users\mlee\anaconda3\Lib\site-packages\jupyter_core\utils\__init__.py", line 165, in wrapped
    return loop.run_until_complete(inner)
           ^^^^^^^^^^^^^^^^^^^^^^^^^^^^^^
  File "C:\Users\mlee\anaconda3\Lib\asyncio\base_events.py", line 687, in run_until_complete
    return future.result()
           ^^^^^^^^^^^^^^^
  File "C:\Users\mlee\anaconda3\Lib\site-packages\nbclient\client.py", line 705, in async_execute
    await self.async_execute_cell(
  File "C:\Users\mlee\anaconda3\Lib\site-packages\nbclient\client.py", line 1058, in async_execute_cell
    await self._check_raise_for_error(cell, cell_index, exec_reply)
  File "C:\Users\mlee\anaconda3\Lib\site-packages\nbclient\client.py", line 914, in _check_raise_for_error
    raise CellExecutionError.from_cell_and_msg(cell, exec_reply_content)
nbclient.exceptions.CellExecutionError: An error occurred while executing the following cell:
------------------
X = train[inc_fts]     # 선택한 정보들
y = train['Survived']  # 실제 생존 여부
X_test = test[inc_fts] # 예측해야 할 데이터의 정보들

print(X.shape, y.shape, X_test.shape) # 행과 열 출력 
------------------


[1;31m---------------------------------------------------------------------------[0m
[1;31mNameError[0m                                 Traceback (most recent call last)
Cell [1;32mIn[2], line 1[0m
[1;32m----> 1[0m X [38;5;241m=[39m train[inc_fts]     [38;5;66;03m# 선택한 정보들[39;00m
[0;32m      2[0m y [38;5;241m=[39m train[[38;5;124m'[39m[38;5;124mSurvived[39m[38;5;124m'[39m]  [38;5;66;03m# 실제 생존 여부[39;00m
[0;32m      3[0m X_test [38;5;241m=[39m test[inc_fts] [38;5;66;03m# 예측해야 할 데이터의 정보들[39;00m

[1;31mNameError[0m: name 'train' is not defined

